<sdf version='1.7'>
  <world name='default'>
    <plugin name='gazebo_ros_state' filename='libgazebo_ros_state.so'>
      <update_rate>1.0</update_rate>
    </plugin>
    <light name='sun_directional' type='directional'>
      <cast_shadows>1</cast_shadows>
      <pose>200 0 14 0 -0 0</pose>
      <diffuse>0.7 0.7 0.7 1</diffuse>
      <specular>0.001 0.001 0.001 1</specular>
      <direction>-1 -0.1 -0.15</direction>
      <attenuation>
        <range>1000</range>
        <constant>1</constant>
        <linear>0</linear>
      </attenuation>
      <spot>
        <inner_angle>0</inner_angle>
        <outer_angle>0</outer_angle>
        <falloff>0</falloff>
      </spot>
    </light>
    <scene>
      <ambient>0.3 0.3 0.3 1</ambient>
      <background>0 0 0 1</background>
      <origin_visual>0</origin_visual>
      <grid>0</grid>
      <shadows>1</shadows>
    </scene>
    <physics type='ode'>
      <max_step_size>0.001</max_step_size>
      <real_time_factor>1</real_time_factor>
      <real_time_update_rate>1000</real_time_update_rate>
      <atmosphere type='adiabatic'/>
    </physics>
    <model name='moon'>
      <static>1</static>
      <link name='link'>
        <collision name='collision'>
          <geometry>
            <heightmap>
              <uri>model://moon/materials/heightmap/moon.png</uri>
              <size>100 100 6</size>
              <pos>0 0 0</pos>
              <texture>
                <size>10</size>
                <diffuse>__default__</diffuse>
                <normal>__default__</normal>
              </texture>
              <blend>
                <min_height>0</min_height>
                <fade_dist>0</fade_dist>
              </blend>
            </heightmap>
          </geometry>
          <max_contacts>10</max_contacts>
          <surface>
            <contact>
              <ode/>
            </contact>
            <bounce/>
            <friction>
              <torsional>
                <ode/>
              </torsional>
              <ode/>
            </friction>
          </surface>
        </collision>
        <visual name='visual_abcedf'>
          <cast_shadows>1</cast_shadows>
          <geometry>
            <heightmap>
              <texture>
                <diffuse>model://moon/materials/textures/ground_1.jpg</diffuse>
                <normal>model://moon/materials/textures/ground_normal.jpg</normal>
                <size>1</size>
              </texture>
              <uri>model://moon/materials/heightmap/moon.png</uri>
              <size>100 100 6</size>
              <pos>0 0 0</pos>
              <blend>
                <min_height>0</min_height>
                <fade_dist>0</fade_dist>
              </blend>
            </heightmap>
          </geometry>
        </visual>
        <self_collide>0</self_collide>
        <enable_wind>0</enable_wind>
        <kinematic>0</kinematic>
      </link>
    </model>
    <gravity>0 0 -1.62</gravity>
    <magnetic_field>6e-06 2.3e-05 -4.2e-05</magnetic_field>
    <atmosphere type='adiabatic'/>
    <audio>
      <device>default</device>
    </audio>
    <wind/>
    <spherical_coordinates>
      <surface_model>EARTH_WGS84</surface_model>
      <latitude_deg>0</latitude_deg>
      <longitude_deg>0</longitude_deg>
      <elevation>0</elevation>
      <heading_deg>0</heading_deg>
    </spherical_coordinates>
    <model name='rover'>
      <link name='base_link'>
        <inertial>
          <pose>0.002339 0 0.000667 0 -0 0</pose>
          <mass>1.01201</mass>
          <inertia>
            <ixx>0.00999029</ixx>
            <ixy>0</ixy>
            <ixz>-0.000152155</ixz>
            <iyy>0.0187945</iyy>
            <iyz>0</iyz>
            <izz>0.0250209</izz>
          </inertia>
        </inertial>
        <collision name='base_link_fixed_joint_lump__body_box_link_collision'>
          <pose>0 0 0 0 -0 0</pose>
          <geometry>
            <box>
              <size>0.43 0.29 0.1</size>
            </box>
          </geometry>
          <surface>
            <contact>
              <ode/>
            </contact>
            <friction>
              <ode/>
              <torsional>
                <ode/>
              </torsional>
            </friction>
            <bounce/>
          </surface>
          <max_contacts>10</max_contacts>
        </collision>
        <collision name='base_link_fixed_joint_lump__camera_link_collision_1'>
          <pose>0.215 0 0.065 1.9708 -0 1.5708</pose>
          <geometry>
            <mesh>
              <scale>0.001 0.001 0.001</scale>
              <uri>model://rover_description/meshes/sensors/asus_xtion/asus_xtion_pro_live.dae</uri>
            </mesh>
          </geometry>
          <surface>
            <contact>
              <ode/>
            </contact>
            <friction>
              <ode/>
              <torsional>
                <ode/>
              </torsional>
            </friction>
            <bounce/>
          </surface>
          <max_contacts>10</max_contacts>
        </collision>
        <collision name='base_link_fixed_joint_lump__imu_link_collision_2'>
          <pose>0 0 -0.04 0 -0 0</pose>
          <geometry>
            <box>
              <size>0.001 0.001 0.001</size>
            </box>
          </geometry>
          <surface>
            <contact>
              <ode/>
            </contact>
            <friction>
              <ode/>
              <torsional>
                <ode/>
              </torsional>
            </friction>
            <bounce/>
          </surface>
          <max_contacts>10</max_contacts>
        </collision>
        <collision name='base_link_fixed_joint_lump__laser_base_link_collision_3'>
          <pose>0.17 0 -0.045 0 -0 0</pose>
          <geometry>
            <box>
              <size>0.01 0.01 0.01</size>
            </box>
          </geometry>
          <surface>
            <contact>
              <ode/>
            </contact>
            <friction>
              <ode/>
              <torsional>
                <ode/>
              </torsional>
            </friction>
            <bounce/>
          </surface>
          <max_contacts>10</max_contacts>
        </collision>
        <visual name='base_link_visual'>
          <pose>0 0 0 0 -0 0</pose>
          <geometry>
            <box>
              <size>0.01 0.01 0.01</size>
            </box>
          </geometry>
          <material>
            <script>
              <name>Gazebo/Orange</name>
              <uri>file://media/materials/scripts/gazebo.material</uri>
            </script>
          </material>
        </visual>
        <visual name='base_link_fixed_joint_lump__body_box_link_visual_1'>
          <pose>0 0 0 0 -0 0</pose>
          <geometry>
            <mesh>
              <scale>1 1 1</scale>
              <uri>model://rover_description/meshes/bases/body_box.stl</uri>
            </mesh>
          </geometry>
          <material>
            <script>
              <name>Gazebo/White</name>
              <uri>file://media/materials/scripts/gazebo.material</uri>
            </script>
          </material>
        </visual>
        <visual name='base_link_fixed_joint_lump__camera_link_visual_2'>
          <pose>0.215 0 0.065 1.9708 -0 1.5708</pose>
          <geometry>
            <mesh>
              <scale>0.001 0.001 0.001</scale>
              <uri>model://rover_description/meshes/sensors/asus_xtion/asus_xtion_pro_live.dae</uri>
            </mesh>
          </geometry>
        </visual>
        <visual name='base_link_fixed_joint_lump__imu_link_visual_3'>
          <pose>0 0 -0.04 0 -0 0</pose>
          <geometry>
            <box>
              <size>0.03 0.02 0.01</size>
            </box>
          </geometry>
          <material>
            <script>
              <name>Gazebo/Blue</name>
              <uri>file://media/materials/scripts/gazebo.material</uri>
            </script>
          </material>
        </visual>
        <visual name='base_link_fixed_joint_lump__laser_base_link_visual_4'>
          <pose>0.17 0 -0.045 0 -0 0</pose>
          <geometry>
            <mesh>
              <scale>1 1 1</scale>
              <uri>model://rover_description/meshes/sensors/hokuyo/hokuyo_ust_20lx.dae</uri>
            </mesh>
          </geometry>
          <material>
            <script>
              <name>Gazebo/DarkGrey</name>
              <uri>file://media/materials/scripts/gazebo.material</uri>
            </script>
          </material>
        </visual>
        <sensor name='camera' type='depth'>
          <visualize>1</visualize>
          <update_rate>30</update_rate>
          <camera>
            <horizontal_fov>1.09956</horizontal_fov>
            <image>
              <format>B8G8R8</format>
              <width>640</width>
              <height>480</height>
            </image>
            <clip>
              <near>0.3</near>
              <far>8</far>
            </clip>
            <distortion>
              <k1>1e-08</k1>
              <k2>1e-08</k2>
              <k3>1e-08</k3>
              <p1>1e-08</p1>
              <p2>1e-08</p2>
            </distortion>
          </camera>
          <plugin name='depth_camera_controller' filename='libgazebo_ros_camera.so'>
            <ros>
              <qos>
                <topic name='/camera/camera_info'>
                  <publisher>
                    <reliability>best_effort</reliability>
                  </publisher>
                </topic>
                <topic name='/camera/image_raw'>
                  <publisher>
                    <reliability>best_effort</reliability>
                  </publisher>
                </topic>
                <topic name='/camera/image_raw/compressed'>
                  <publisher>
                    <reliability>best_effort</reliability>
                  </publisher>
                </topic>
                <topic name='/camera/image_raw/compressedDepth'>
                  <publisher>
                    <reliability>best_effort</reliability>
                  </publisher>
                </topic>
                <topic name='/camera/image_raw/theora'>
                  <publisher>
                    <reliability>best_effort</reliability>
                  </publisher>
                </topic>
                <topic name='/camera/points'>
                  <publisher>
                    <reliability>best_effort</reliability>
                  </publisher>
                </topic>
                <topic name='/camera/depth/camera_info'>
                  <publisher>
                    <reliability>best_effort</reliability>
                  </publisher>
                </topic>
                <topic name='/camera/depth/image_raw'>
                  <publisher>
                    <reliability>best_effort</reliability>
                  </publisher>
                </topic>
                <topic name='/camera/depth/image_raw/compressed'>
                  <publisher>
                    <reliability>best_effort</reliability>
                  </publisher>
                </topic>
                <topic name='/camera/depth/image_raw/compressedDepth'>
                  <publisher>
                    <reliability>best_effort</reliability>
                  </publisher>
                </topic>
                <topic name='/camera/depth/image_raw/theora'>
                  <publisher>
                    <reliability>best_effort</reliability>
                  </publisher>
                </topic>
              </qos>
            </ros>
            <frame_name>camera_frame</frame_name>
            <min_depth>0.3</min_depth>
            <max_depth>8.0</max_depth>
          </plugin>
          <pose>0.215 0 0.065 0 0.4 0</pose>
        </sensor>
        <sensor name='imu_sensor' type='imu'>
          <plugin name='imu_controller' filename='libgazebo_ros_imu_sensor.so'>
            <ros>
              <remapping>~/out:=imu</remapping>
              <qos>
                <topic name='imu'>
                  <publisher>
                    <reliability>best_effort</reliability>
                  </publisher>
                </topic>
              </qos>
            </ros>
            <initial_orientation_as_reference>0</initial_orientation_as_reference>
            <frame_name>imu_link</frame_name>
          </plugin>
          <always_on>1</always_on>
          <update_rate>200</update_rate>
          <visualize>1</visualize>
          <imu>
            <angular_velocity>
              <x>
                <noise type='gaussian'>
                  <mean>0</mean>
                  <stddev>0.0002</stddev>
                  <bias_mean>7.5e-06</bias_mean>
                  <bias_stddev>8e-07</bias_stddev>
                </noise>
              </x>
              <y>
                <noise type='gaussian'>
                  <mean>0</mean>
                  <stddev>0.0002</stddev>
                  <bias_mean>7.5e-06</bias_mean>
                  <bias_stddev>8e-07</bias_stddev>
                </noise>
              </y>
              <z>
                <noise type='gaussian'>
                  <mean>0</mean>
                  <stddev>0.0002</stddev>
                  <bias_mean>7.5e-06</bias_mean>
                  <bias_stddev>8e-07</bias_stddev>
                </noise>
              </z>
            </angular_velocity>
            <linear_acceleration>
              <x>
                <noise type='gaussian'>
                  <mean>0</mean>
                  <stddev>0.017</stddev>
                  <bias_mean>0.1</bias_mean>
                  <bias_stddev>0.001</bias_stddev>
                </noise>
              </x>
              <y>
                <noise type='gaussian'>
                  <mean>0</mean>
                  <stddev>0.017</stddev>
                  <bias_mean>0.1</bias_mean>
                  <bias_stddev>0.001</bias_stddev>
                </noise>
              </y>
              <z>
                <noise type='gaussian'>
                  <mean>0</mean>
                  <stddev>0.017</stddev>
                  <bias_mean>0.1</bias_mean>
                  <bias_stddev>0.001</bias_stddev>
                </noise>
              </z>
            </linear_acceleration>
          </imu>
          <pose>0 0 -0.04 0 -0 0</pose>
        </sensor>
        <sensor name='hokuyo_sensor' type='gpu_ray'>
          <visualize>1</visualize>
          <update_rate>50</update_rate>
          <ray>
            <scan>
              <horizontal>
                <samples>30</samples>
                <resolution>1</resolution>
                <min_angle>-1</min_angle>
                <max_angle>1</max_angle>
              </horizontal>
              <vertical>
                <samples>1</samples>
                <min_angle>0</min_angle>
                <max_angle>0</max_angle>
              </vertical>
            </scan>
            <range>
              <min>0.06</min>
              <max>5</max>
              <resolution>0.0043593</resolution>
            </range>
            <noise>
              <type>gaussian</type>
              <mean>0</mean>
              <stddev>0.01</stddev>
            </noise>
          </ray>
          <plugin name='laser_controller' filename='libgazebo_ros_ray_sensor.so'>
            <ros>
              <remapping>~/out:=scan</remapping>
              <qos>
                <topic name='scan'>
                  <publisher>
                    <reliability>best_effort</reliability>
                  </publisher>
                </topic>
              </qos>
            </ros>
            <output_type>sensor_msgs/LaserScan</output_type>
            <frame_name>laser_link</frame_name>
          </plugin>
          <pose>0.17 0 0.005 0 -0 0</pose>
        </sensor>
        <self_collide>0</self_collide>
        <enable_wind>0</enable_wind>
        <kinematic>0</kinematic>
      </link>
      <joint name='diff_brace_joint' type='revolute'>
        <pose relative_to='base_link'>0 0 0.0681 0 -0 0</pose>
        <parent>base_link</parent>
        <child>diff_brace_link</child>
        <axis>
          <xyz>0 0 1</xyz>
          <limit>
            <lower>-0.785398</lower>
            <upper>0.785398</upper>
            <effort>100</effort>
            <velocity>30</velocity>
          </limit>
          <dynamics>
            <spring_reference>0</spring_reference>
            <spring_stiffness>0</spring_stiffness>
          </dynamics>
        </axis>
        <physics>
          <provide_feedback>1</provide_feedback>
          <ode>
            <implicit_spring_damper>1</implicit_spring_damper>
            <cfm_damping>1</cfm_damping>
            <limit>
              <cfm>0</cfm>
              <erp>0.2</erp>
            </limit>
            <provide_feedback>1</provide_feedback>
          </ode>
        </physics>
      </joint>
      <link name='diff_brace_link'>
        <pose relative_to='diff_brace_joint'>0 0 0 0 -0 0</pose>
        <inertial>
          <pose>0 0 0 0 -0 1.5708</pose>
          <mass>0.1</mass>
          <inertia>
            <ixx>5.04167e-05</ixx>
            <ixy>0</ixy>
            <ixz>0</ixz>
            <iyy>0.000775208</iyy>
            <iyz>0</iyz>
            <izz>0.000775208</izz>
          </inertia>
        </inertial>
        <collision name='diff_brace_link_collision'>
          <pose>0 0 0 0 -0 1.5708</pose>
          <geometry>
            <box>
              <size>0.3 0.055 0.055</size>
            </box>
          </geometry>
          <surface>
            <contact>
              <ode/>
            </contact>
            <friction>
              <ode/>
              <torsional>
                <ode/>
              </torsional>
            </friction>
            <bounce/>
          </surface>
          <max_contacts>10</max_contacts>
        </collision>
        <visual name='diff_brace_link_visual'>
          <pose>0 0 0 0 -0 0</pose>
          <geometry>
            <mesh>
              <scale>1 1 1</scale>
              <uri>model://rover_description/meshes/bases/differential.stl</uri>
            </mesh>
          </geometry>
          <material>
            <script>
              <name>Gazebo/White</name>
              <uri>file://media/materials/scripts/gazebo.material</uri>
            </script>
          </material>
        </visual>
        <self_collide>0</self_collide>
        <enable_wind>0</enable_wind>
        <kinematic>0</kinematic>
      </link>
      <joint name='left_rocker_joint' type='revolute'>
        <pose relative_to='base_link'>0.071 0.155 0.0118 0 -0 0</pose>
        <parent>base_link</parent>
        <child>left_rocker_link</child>
        <axis>
          <xyz>0 1 0</xyz>
          <limit>
            <effort>100</effort>
            <velocity>30</velocity>
            <lower>-1e+16</lower>
            <upper>1e+16</upper>
          </limit>
          <dynamics>
            <spring_reference>0</spring_reference>
            <spring_stiffness>0</spring_stiffness>
          </dynamics>
        </axis>
        <physics>
          <provide_feedback>1</provide_feedback>
          <ode>
            <implicit_spring_damper>1</implicit_spring_damper>
            <cfm_damping>1</cfm_damping>
            <limit>
              <cfm>0</cfm>
              <erp>0.2</erp>
            </limit>
            <provide_feedback>1</provide_feedback>
          </ode>
        </physics>
      </joint>
      <link name='left_rocker_link'>
        <pose relative_to='left_rocker_joint'>0 0 0 0 -0 0</pose>
        <inertial>
          <pose>0 0 0 0 -0 0</pose>
          <mass>0.25</mass>
          <inertia>
            <ixx>0.00196042</ixx>
            <ixy>0</ixy>
            <ixz>0</ixz>
            <iyy>0.00406042</iyy>
            <iyz>0</iyz>
            <izz>0.00560417</izz>
          </inertia>
        </inertial>
        <collision name='left_rocker_link_collision'>
          <pose>0 0 0 0 -0 0</pose>
          <geometry>
            <box>
              <size>0.43 0.29 0.1</size>
            </box>
          </geometry>
          <surface>
            <contact>
              <ode/>
            </contact>
            <friction>
              <ode/>
              <torsional>
                <ode/>
              </torsional>
            </friction>
            <bounce/>
          </surface>
          <max_contacts>10</max_contacts>
        </collision>
        <visual name='left_rocker_link_visual'>
          <pose>0 0 0 0 -0 0</pose>
          <geometry>
            <mesh>
              <scale>1 1 1</scale>
              <uri>model://rover_description/meshes/bases/left_rocker_asm.stl</uri>
            </mesh>
          </geometry>
          <material>
            <script>
              <name>Gazebo/White</name>
              <uri>file://media/materials/scripts/gazebo.material</uri>
            </script>
          </material>
        </visual>
        <self_collide>0</self_collide>
        <enable_wind>0</enable_wind>
        <kinematic>0</kinematic>
      </link>
      <joint name='front_left_corner_joint' type='revolute'>
        <pose relative_to='left_rocker_link'>0.2116 0.075 -0.0279 0 -0 0</pose>
        <parent>left_rocker_link</parent>
        <child>front_left_corner_link</child>
        <axis>
          <xyz>0 0 1</xyz>
          <limit>
            <effort>1000</effort>
            <velocity>30</velocity>
            <lower>-1e+16</lower>
            <upper>1e+16</upper>
          </limit>
          <dynamics>
            <damping>0</damping>
            <friction>0</friction>
            <spring_reference>0</spring_reference>
            <spring_stiffness>0</spring_stiffness>
          </dynamics>
        </axis>
        <physics>
          <provide_feedback>1</provide_feedback>
          <ode>
            <limit>
              <cfm>0</cfm>
              <erp>0.2</erp>
            </limit>
            <provide_feedback>1</provide_feedback>
          </ode>
        </physics>
      </joint>
      <link name='front_left_corner_link'>
        <pose relative_to='front_left_corner_joint'>0 0 0 0 -0 0</pose>
        <inertial>
          <pose>0 0 0 0 -0 0</pose>
          <mass>0.25</mass>
          <inertia>
            <ixx>0.00196042</ixx>
            <ixy>0</ixy>
            <ixz>0</ixz>
            <iyy>0.00406042</iyy>
            <iyz>0</iyz>
            <izz>0.00560417</izz>
          </inertia>
        </inertial>
        <collision name='front_left_corner_link_collision'>
          <pose>0 0 0 0 -0 0</pose>
          <geometry>
            <box>
              <size>0.43 0.29 0.1</size>
            </box>
          </geometry>
          <surface>
            <contact>
              <ode/>
            </contact>
            <friction>
              <ode/>
              <torsional>
                <ode/>
              </torsional>
            </friction>
            <bounce/>
          </surface>
          <max_contacts>10</max_contacts>
        </collision>
        <visual name='front_left_corner_link_visual'>
          <pose>0 0 0 0 -0 0</pose>
          <geometry>
            <mesh>
              <scale>1 1 1</scale>
              <uri>model://rover_description/meshes/bases/front_left_steering_asm.stl</uri>
            </mesh>
          </geometry>
          <material>
            <script>
              <name>Gazebo/White</name>
              <uri>file://media/materials/scripts/gazebo.material</uri>
            </script>
          </material>
        </visual>
        <self_collide>0</self_collide>
        <enable_wind>0</enable_wind>
        <kinematic>0</kinematic>
      </link>
      <joint name='front_left_wheel_joint' type='revolute'>
        <pose relative_to='front_left_corner_link'>0 0 -0.132 0 -0 0</pose>
        <parent>front_left_corner_link</parent>
        <child>front_left_wheel_link</child>
        <axis>
          <xyz>0 1 0</xyz>
          <limit>
            <effort>1000</effort>
            <velocity>30</velocity>
            <lower>-1e+16</lower>
            <upper>1e+16</upper>
          </limit>
          <dynamics>
            <damping>0</damping>
            <friction>0</friction>
            <spring_reference>0</spring_reference>
            <spring_stiffness>0</spring_stiffness>
          </dynamics>
        </axis>
        <physics>
          <provide_feedback>1</provide_feedback>
          <ode>
            <limit>
              <cfm>0</cfm>
              <erp>0.2</erp>
            </limit>
            <provide_feedback>1</provide_feedback>
          </ode>
        </physics>
      </joint>
      <link name='front_left_wheel_link'>
        <pose relative_to='front_left_wheel_joint'>0 0 0 0 -0 0</pose>
        <inertial>
          <pose>0 0 0 0 -0 0</pose>
          <mass>0.25</mass>
          <inertia>
            <ixx>0.000433333</ixx>
            <ixy>0</ixy>
            <ixz>0</ixz>
            <iyy>0.000433333</iyy>
            <iyz>0</iyz>
            <izz>0.00045</izz>
          </inertia>
        </inertial>
        <collision name='front_left_wheel_link_collision'>
          <pose>0 0 0 1.5708 -0 0</pose>
          <geometry>
            <cylinder>
              <length>0.1</length>
              <radius>0.06</radius>
            </cylinder>
          </geometry>
          <surface>
            <contact>
              <ode>
                <kp>1e+07</kp>
                <kd>1</kd>
              </ode>
            </contact>
            <friction>
              <ode>
                <mu>100</mu>
                <mu2>100</mu2>
                <fdir1>1 0 0</fdir1>
              </ode>
              <torsional>
                <ode/>
              </torsional>
            </friction>
            <bounce/>
          </surface>
          <max_contacts>10</max_contacts>
        </collision>
        <visual name='front_left_wheel_link_visual'>
          <pose>0 0 0 1.5708 -0 0</pose>
          <geometry>
            <mesh>
              <scale>1 1 1</scale>
              <uri>model://rover_description/meshes/wheels/wheel_asm.stl</uri>
            </mesh>
          </geometry>
          <material>
            <script>
              <name>Gazebo/DarkGray</name>
              <uri>file://media/materials/scripts/gazebo.material</uri>
            </script>
          </material>
        </visual>
        <gravity>1</gravity>
        <self_collide>0</self_collide>
        <enable_wind>0</enable_wind>
        <kinematic>0</kinematic>
      </link>
      <joint name='left_bogie_joint' type='revolute'>
        <pose relative_to='left_rocker_link'>-0.181 0.025 -0.062 0 -0 0</pose>
        <parent>left_rocker_link</parent>
        <child>left_bogie_link</child>
        <axis>
          <xyz>0 1 0</xyz>
          <limit>
            <lower>-0.785398</lower>
            <upper>0.785398</upper>
            <effort>100</effort>
            <velocity>30</velocity>
          </limit>
          <dynamics>
            <spring_reference>0</spring_reference>
            <spring_stiffness>0</spring_stiffness>
          </dynamics>
        </axis>
        <physics>
          <provide_feedback>1</provide_feedback>
          <ode>
            <implicit_spring_damper>1</implicit_spring_damper>
            <cfm_damping>1</cfm_damping>
            <limit>
              <cfm>0</cfm>
              <erp>0.2</erp>
            </limit>
            <provide_feedback>1</provide_feedback>
          </ode>
        </physics>
      </joint>
      <link name='left_bogie_link'>
        <pose relative_to='left_bogie_joint'>0 0 0 0 -0 0</pose>
        <inertial>
          <pose>0 0 0 0 -0 0</pose>
          <mass>0.25</mass>
          <inertia>
            <ixx>0.00196042</ixx>
            <ixy>0</ixy>
            <ixz>0</ixz>
            <iyy>0.00406042</iyy>
            <iyz>0</iyz>
            <izz>0.00560417</izz>
          </inertia>
        </inertial>
        <collision name='left_bogie_link_collision'>
          <pose>0 0 0 0 -0 0</pose>
          <geometry>
            <box>
              <size>0.43 0.29 0.1</size>
            </box>
          </geometry>
          <surface>
            <contact>
              <ode/>
            </contact>
            <friction>
              <ode/>
              <torsional>
                <ode/>
              </torsional>
            </friction>
            <bounce/>
          </surface>
          <max_contacts>10</max_contacts>
        </collision>
        <visual name='left_bogie_link_visual'>
          <pose>0 0 0 0 -0 0</pose>
          <geometry>
            <mesh>
              <scale>1 1 1</scale>
              <uri>model://rover_description/meshes/bases/left_bogie_asm.stl</uri>
            </mesh>
          </geometry>
          <material>
            <script>
              <name>Gazebo/White</name>
              <uri>file://media/materials/scripts/gazebo.material</uri>
            </script>
          </material>
        </visual>
        <self_collide>0</self_collide>
        <enable_wind>0</enable_wind>
        <kinematic>0</kinematic>
      </link>
      <joint name='back_left_corner_joint' type='revolute'>
        <pose relative_to='left_bogie_link'>-0.149 0.05 0.0338 0 -0 0</pose>
        <parent>left_bogie_link</parent>
        <child>back_left_corner_link</child>
        <axis>
          <xyz>0 0 1</xyz>
          <limit>
            <effort>1000</effort>
            <velocity>30</velocity>
            <lower>-1e+16</lower>
            <upper>1e+16</upper>
          </limit>
          <dynamics>
            <damping>0</damping>
            <friction>0</friction>
            <spring_reference>0</spring_reference>
            <spring_stiffness>0</spring_stiffness>
          </dynamics>
        </axis>
        <physics>
          <provide_feedback>1</provide_feedback>
          <ode>
            <limit>
              <cfm>0</cfm>
              <erp>0.2</erp>
            </limit>
            <provide_feedback>1</provide_feedback>
          </ode>
        </physics>
      </joint>
      <link name='back_left_corner_link'>
        <pose relative_to='back_left_corner_joint'>0 0 0 0 -0 0</pose>
        <inertial>
          <pose>0 0 0 0 -0 0</pose>
          <mass>0.25</mass>
          <inertia>
            <ixx>0.00196042</ixx>
            <ixy>0</ixy>
            <ixz>0</ixz>
            <iyy>0.00406042</iyy>
            <iyz>0</iyz>
            <izz>0.00560417</izz>
          </inertia>
        </inertial>
        <collision name='back_left_corner_link_collision'>
          <pose>0 0 0 0 -0 0</pose>
          <geometry>
            <box>
              <size>0.43 0.29 0.1</size>
            </box>
          </geometry>
          <surface>
            <contact>
              <ode/>
            </contact>
            <friction>
              <ode/>
              <torsional>
                <ode/>
              </torsional>
            </friction>
            <bounce/>
          </surface>
          <max_contacts>10</max_contacts>
        </collision>
        <visual name='back_left_corner_link_visual'>
          <pose>0 0 0 0 -0 0</pose>
          <geometry>
            <mesh>
              <scale>1 1 1</scale>
              <uri>model://rover_description/meshes/bases/back_left_steering_asm.stl</uri>
            </mesh>
          </geometry>
          <material>
            <script>
              <name>Gazebo/White</name>
              <uri>file://media/materials/scripts/gazebo.material</uri>
            </script>
          </material>
        </visual>
        <self_collide>0</self_collide>
        <enable_wind>0</enable_wind>
        <kinematic>0</kinematic>
      </link>
      <joint name='back_left_wheel_joint' type='revolute'>
        <pose relative_to='back_left_corner_link'>0 0 -0.132 0 -0 0</pose>
        <parent>back_left_corner_link</parent>
        <child>back_left_wheel_link</child>
        <axis>
          <xyz>0 1 0</xyz>
          <limit>
            <effort>1000</effort>
            <velocity>30</velocity>
            <lower>-1e+16</lower>
            <upper>1e+16</upper>
          </limit>
          <dynamics>
            <damping>0</damping>
            <friction>0</friction>
            <spring_reference>0</spring_reference>
            <spring_stiffness>0</spring_stiffness>
          </dynamics>
        </axis>
        <physics>
          <provide_feedback>1</provide_feedback>
          <ode>
            <limit>
              <cfm>0</cfm>
              <erp>0.2</erp>
            </limit>
            <provide_feedback>1</provide_feedback>
          </ode>
        </physics>
      </joint>
      <link name='back_left_wheel_link'>
        <pose relative_to='back_left_wheel_joint'>0 0 0 0 -0 0</pose>
        <inertial>
          <pose>0 0 0 0 -0 0</pose>
          <mass>0.25</mass>
          <inertia>
            <ixx>0.000433333</ixx>
            <ixy>0</ixy>
            <ixz>0</ixz>
            <iyy>0.000433333</iyy>
            <iyz>0</iyz>
            <izz>0.00045</izz>
          </inertia>
        </inertial>
        <collision name='back_left_wheel_link_collision'>
          <pose>0 0 0 1.5708 -0 0</pose>
          <geometry>
            <cylinder>
              <length>0.1</length>
              <radius>0.06</radius>
            </cylinder>
          </geometry>
          <surface>
            <contact>
              <ode>
                <kp>1e+07</kp>
                <kd>1</kd>
              </ode>
            </contact>
            <friction>
              <ode>
                <mu>100</mu>
                <mu2>100</mu2>
                <fdir1>1 0 0</fdir1>
              </ode>
              <torsional>
                <ode/>
              </torsional>
            </friction>
            <bounce/>
          </surface>
          <max_contacts>10</max_contacts>
        </collision>
        <visual name='back_left_wheel_link_visual'>
          <pose>0 0 0 1.5708 -0 0</pose>
          <geometry>
            <mesh>
              <scale>1 1 1</scale>
              <uri>model://rover_description/meshes/wheels/wheel_asm.stl</uri>
            </mesh>
          </geometry>
          <material>
            <script>
              <name>Gazebo/DarkGray</name>
              <uri>file://media/materials/scripts/gazebo.material</uri>
            </script>
          </material>
        </visual>
        <gravity>1</gravity>
        <self_collide>0</self_collide>
        <enable_wind>0</enable_wind>
        <kinematic>0</kinematic>
      </link>
      <joint name='mid_left_wheel_joint' type='revolute'>
        <pose relative_to='left_bogie_link'>0.1063 0.0929 -0.0959 0 -0 0</pose>
        <parent>left_bogie_link</parent>
        <child>mid_left_wheel_link</child>
        <axis>
          <xyz>0 1 0</xyz>
          <limit>
            <effort>1000</effort>
            <velocity>30</velocity>
            <lower>-1e+16</lower>
            <upper>1e+16</upper>
          </limit>
          <dynamics>
            <damping>0</damping>
            <friction>0</friction>
            <spring_reference>0</spring_reference>
            <spring_stiffness>0</spring_stiffness>
          </dynamics>
        </axis>
        <physics>
          <provide_feedback>1</provide_feedback>
          <ode>
            <limit>
              <cfm>0</cfm>
              <erp>0.2</erp>
            </limit>
            <provide_feedback>1</provide_feedback>
          </ode>
        </physics>
      </joint>
      <link name='mid_left_wheel_link'>
        <pose relative_to='mid_left_wheel_joint'>0 0 0 0 -0 0</pose>
        <inertial>
          <pose>0 0 0 0 -0 0</pose>
          <mass>0.25</mass>
          <inertia>
            <ixx>0.000433333</ixx>
            <ixy>0</ixy>
            <ixz>0</ixz>
            <iyy>0.000433333</iyy>
            <iyz>0</iyz>
            <izz>0.00045</izz>
          </inertia>
        </inertial>
        <collision name='mid_left_wheel_link_collision'>
          <pose>0 0 0 1.5708 -0 0</pose>
          <geometry>
            <cylinder>
              <length>0.1</length>
              <radius>0.06</radius>
            </cylinder>
          </geometry>
          <surface>
            <contact>
              <ode>
                <kp>1e+07</kp>
                <kd>1</kd>
              </ode>
            </contact>
            <friction>
              <ode>
                <mu>100</mu>
                <mu2>100</mu2>
                <fdir1>1 0 0</fdir1>
              </ode>
              <torsional>
                <ode/>
              </torsional>
            </friction>
            <bounce/>
          </surface>
          <max_contacts>10</max_contacts>
        </collision>
        <visual name='mid_left_wheel_link_visual'>
          <pose>0 0 0 1.5708 -0 0</pose>
          <geometry>
            <mesh>
              <scale>1 1 1</scale>
              <uri>model://rover_description/meshes/wheels/wheel_asm.stl</uri>
            </mesh>
          </geometry>
          <material>
            <script>
              <name>Gazebo/DarkGray</name>
              <uri>file://media/materials/scripts/gazebo.material</uri>
            </script>
          </material>
        </visual>
        <gravity>1</gravity>
        <self_collide>0</self_collide>
        <enable_wind>0</enable_wind>
        <kinematic>0</kinematic>
      </link>
      <joint name='right_rocker_joint' type='revolute'>
        <pose relative_to='base_link'>0.071 -0.155 0.0118 0 -0 0</pose>
        <parent>base_link</parent>
        <child>right_rocker_link</child>
        <axis>
          <xyz>0 1 0</xyz>
          <limit>
            <effort>100</effort>
            <velocity>30</velocity>
            <lower>-1e+16</lower>
            <upper>1e+16</upper>
          </limit>
          <dynamics>
            <spring_reference>0</spring_reference>
            <spring_stiffness>0</spring_stiffness>
          </dynamics>
        </axis>
        <physics>
          <provide_feedback>1</provide_feedback>
          <ode>
            <implicit_spring_damper>1</implicit_spring_damper>
            <cfm_damping>1</cfm_damping>
            <limit>
              <cfm>0</cfm>
              <erp>0.2</erp>
            </limit>
            <provide_feedback>1</provide_feedback>
          </ode>
        </physics>
      </joint>
      <link name='right_rocker_link'>
        <pose relative_to='right_rocker_joint'>0 0 0 0 -0 0</pose>
        <inertial>
          <pose>0 0 0 0 -0 0</pose>
          <mass>0.25</mass>
          <inertia>
            <ixx>0.00196042</ixx>
            <ixy>0</ixy>
            <ixz>0</ixz>
            <iyy>0.00406042</iyy>
            <iyz>0</iyz>
            <izz>0.00560417</izz>
          </inertia>
        </inertial>
        <collision name='right_rocker_link_collision'>
          <pose>0 0 0 0 -0 0</pose>
          <geometry>
            <box>
              <size>0.43 0.29 0.1</size>
            </box>
          </geometry>
          <surface>
            <contact>
              <ode/>
            </contact>
            <friction>
              <ode/>
              <torsional>
                <ode/>
              </torsional>
            </friction>
            <bounce/>
          </surface>
          <max_contacts>10</max_contacts>
        </collision>
        <visual name='right_rocker_link_visual'>
          <pose>0 0 0 0 -0 0</pose>
          <geometry>
            <mesh>
              <scale>1 1 1</scale>
              <uri>model://rover_description/meshes/bases/right_rocker_asm.stl</uri>
            </mesh>
          </geometry>
          <material>
            <script>
              <name>Gazebo/White</name>
              <uri>file://media/materials/scripts/gazebo.material</uri>
            </script>
          </material>
        </visual>
        <self_collide>0</self_collide>
        <enable_wind>0</enable_wind>
        <kinematic>0</kinematic>
      </link>
      <joint name='front_right_corner_joint' type='revolute'>
        <pose relative_to='right_rocker_link'>0.2116 -0.075 -0.0279 0 -0 0</pose>
        <parent>right_rocker_link</parent>
        <child>front_right_corner_link</child>
        <axis>
          <xyz>0 0 1</xyz>
          <limit>
            <effort>1000</effort>
            <velocity>30</velocity>
            <lower>-1e+16</lower>
            <upper>1e+16</upper>
          </limit>
          <dynamics>
            <damping>0</damping>
            <friction>0</friction>
            <spring_reference>0</spring_reference>
            <spring_stiffness>0</spring_stiffness>
          </dynamics>
        </axis>
        <physics>
          <provide_feedback>1</provide_feedback>
          <ode>
            <limit>
              <cfm>0</cfm>
              <erp>0.2</erp>
            </limit>
            <provide_feedback>1</provide_feedback>
          </ode>
        </physics>
      </joint>
      <link name='front_right_corner_link'>
        <pose relative_to='front_right_corner_joint'>0 0 0 0 -0 0</pose>
        <inertial>
          <pose>0 0 0 0 -0 0</pose>
          <mass>0.25</mass>
          <inertia>
            <ixx>0.00196042</ixx>
            <ixy>0</ixy>
            <ixz>0</ixz>
            <iyy>0.00406042</iyy>
            <iyz>0</iyz>
            <izz>0.00560417</izz>
          </inertia>
        </inertial>
        <collision name='front_right_corner_link_collision'>
          <pose>0 0 0 0 -0 0</pose>
          <geometry>
            <box>
              <size>0.43 0.29 0.1</size>
            </box>
          </geometry>
          <surface>
            <contact>
              <ode/>
            </contact>
            <friction>
              <ode/>
              <torsional>
                <ode/>
              </torsional>
            </friction>
            <bounce/>
          </surface>
          <max_contacts>10</max_contacts>
        </collision>
        <visual name='front_right_corner_link_visual'>
          <pose>0 0 0 0 -0 0</pose>
          <geometry>
            <mesh>
              <scale>1 1 1</scale>
              <uri>model://rover_description/meshes/bases/front_right_steering_asm.stl</uri>
            </mesh>
          </geometry>
          <material>
            <script>
              <name>Gazebo/White</name>
              <uri>file://media/materials/scripts/gazebo.material</uri>
            </script>
          </material>
        </visual>
        <self_collide>0</self_collide>
        <enable_wind>0</enable_wind>
        <kinematic>0</kinematic>
      </link>
      <joint name='front_right_wheel_joint' type='revolute'>
        <pose relative_to='front_right_corner_link'>0 0 -0.132 0 -0 0</pose>
        <parent>front_right_corner_link</parent>
        <child>front_right_wheel_link</child>
        <axis>
          <xyz>0 1 0</xyz>
          <limit>
            <effort>1000</effort>
            <velocity>30</velocity>
            <lower>-1e+16</lower>
            <upper>1e+16</upper>
          </limit>
          <dynamics>
            <damping>0</damping>
            <friction>0</friction>
            <spring_reference>0</spring_reference>
            <spring_stiffness>0</spring_stiffness>
          </dynamics>
        </axis>
        <physics>
          <provide_feedback>1</provide_feedback>
          <ode>
            <limit>
              <cfm>0</cfm>
              <erp>0.2</erp>
            </limit>
            <provide_feedback>1</provide_feedback>
          </ode>
        </physics>
      </joint>
      <link name='front_right_wheel_link'>
        <pose relative_to='front_right_wheel_joint'>0 0 0 0 -0 0</pose>
        <inertial>
          <pose>0 0 0 0 -0 0</pose>
          <mass>0.25</mass>
          <inertia>
            <ixx>0.000433333</ixx>
            <ixy>0</ixy>
            <ixz>0</ixz>
            <iyy>0.000433333</iyy>
            <iyz>0</iyz>
            <izz>0.00045</izz>
          </inertia>
        </inertial>
        <collision name='front_right_wheel_link_collision'>
          <pose>0 0 0 -1.5708 0 0</pose>
          <geometry>
            <cylinder>
              <length>0.1</length>
              <radius>0.06</radius>
            </cylinder>
          </geometry>
          <surface>
            <contact>
              <ode>
                <kp>1e+07</kp>
                <kd>1</kd>
              </ode>
            </contact>
            <friction>
              <ode>
                <mu>100</mu>
                <mu2>100</mu2>
                <fdir1>1 0 0</fdir1>
              </ode>
              <torsional>
                <ode/>
              </torsional>
            </friction>
            <bounce/>
          </surface>
          <max_contacts>10</max_contacts>
        </collision>
        <visual name='front_right_wheel_link_visual'>
          <pose>0 0 0 -1.5708 0 0</pose>
          <geometry>
            <mesh>
              <scale>1 1 1</scale>
              <uri>model://rover_description/meshes/wheels/wheel_asm.stl</uri>
            </mesh>
          </geometry>
          <material>
            <script>
              <name>Gazebo/DarkGray</name>
              <uri>file://media/materials/scripts/gazebo.material</uri>
            </script>
          </material>
        </visual>
        <gravity>1</gravity>
        <self_collide>0</self_collide>
        <enable_wind>0</enable_wind>
        <kinematic>0</kinematic>
      </link>
      <joint name='right_bogie_joint' type='revolute'>
        <pose relative_to='right_rocker_link'>-0.181 -0.025 -0.062 0 -0 0</pose>
        <parent>right_rocker_link</parent>
        <child>right_bogie_link</child>
        <axis>
          <xyz>0 1 0</xyz>
          <limit>
            <lower>-0.785398</lower>
            <upper>0.785398</upper>
            <effort>100</effort>
            <velocity>30</velocity>
          </limit>
          <dynamics>
            <spring_reference>0</spring_reference>
            <spring_stiffness>0</spring_stiffness>
          </dynamics>
        </axis>
        <physics>
          <provide_feedback>1</provide_feedback>
          <ode>
            <implicit_spring_damper>1</implicit_spring_damper>
            <cfm_damping>1</cfm_damping>
            <limit>
              <cfm>0</cfm>
              <erp>0.2</erp>
            </limit>
            <provide_feedback>1</provide_feedback>
          </ode>
        </physics>
      </joint>
      <link name='right_bogie_link'>
        <pose relative_to='right_bogie_joint'>0 0 0 0 -0 0</pose>
        <inertial>
          <pose>0 0 0 0 -0 0</pose>
          <mass>0.25</mass>
          <inertia>
            <ixx>0.00196042</ixx>
            <ixy>0</ixy>
            <ixz>0</ixz>
            <iyy>0.00406042</iyy>
            <iyz>0</iyz>
            <izz>0.00560417</izz>
          </inertia>
        </inertial>
        <collision name='right_bogie_link_collision'>
          <pose>0 0 0 0 -0 0</pose>
          <geometry>
            <box>
              <size>0.43 0.29 0.1</size>
            </box>
          </geometry>
          <surface>
            <contact>
              <ode/>
            </contact>
            <friction>
              <ode/>
              <torsional>
                <ode/>
              </torsional>
            </friction>
            <bounce/>
          </surface>
          <max_contacts>10</max_contacts>
        </collision>
        <visual name='right_bogie_link_visual'>
          <pose>0 0 0 0 -0 0</pose>
          <geometry>
            <mesh>
              <scale>1 1 1</scale>
              <uri>model://rover_description/meshes/bases/right_bogie_asm.stl</uri>
            </mesh>
          </geometry>
          <material>
            <script>
              <name>Gazebo/White</name>
              <uri>file://media/materials/scripts/gazebo.material</uri>
            </script>
          </material>
        </visual>
        <self_collide>0</self_collide>
        <enable_wind>0</enable_wind>
        <kinematic>0</kinematic>
      </link>
      <joint name='back_right_corner_joint' type='revolute'>
        <pose relative_to='right_bogie_link'>-0.149 -0.05 0.0338 0 -0 0</pose>
        <parent>right_bogie_link</parent>
        <child>back_right_corner_link</child>
        <axis>
          <xyz>0 0 1</xyz>
          <limit>
            <effort>1000</effort>
            <velocity>30</velocity>
            <lower>-1e+16</lower>
            <upper>1e+16</upper>
          </limit>
          <dynamics>
            <damping>0</damping>
            <friction>0</friction>
            <spring_reference>0</spring_reference>
            <spring_stiffness>0</spring_stiffness>
          </dynamics>
        </axis>
        <physics>
          <provide_feedback>1</provide_feedback>
          <ode>
            <limit>
              <cfm>0</cfm>
              <erp>0.2</erp>
            </limit>
            <provide_feedback>1</provide_feedback>
          </ode>
        </physics>
      </joint>
      <link name='back_right_corner_link'>
        <pose relative_to='back_right_corner_joint'>0 0 0 0 -0 0</pose>
        <inertial>
          <pose>0 0 0 0 -0 0</pose>
          <mass>0.25</mass>
          <inertia>
            <ixx>0.00196042</ixx>
            <ixy>0</ixy>
            <ixz>0</ixz>
            <iyy>0.00406042</iyy>
            <iyz>0</iyz>
            <izz>0.00560417</izz>
          </inertia>
        </inertial>
        <collision name='back_right_corner_link_collision'>
          <pose>0 0 0 0 -0 0</pose>
          <geometry>
            <box>
              <size>0.43 0.29 0.1</size>
            </box>
          </geometry>
          <surface>
            <contact>
              <ode/>
            </contact>
            <friction>
              <ode/>
              <torsional>
                <ode/>
              </torsional>
            </friction>
            <bounce/>
          </surface>
          <max_contacts>10</max_contacts>
        </collision>
        <visual name='back_right_corner_link_visual'>
          <pose>0 0 0 0 -0 0</pose>
          <geometry>
            <mesh>
              <scale>1 1 1</scale>
              <uri>model://rover_description/meshes/bases/back_right_steering_asm.stl</uri>
            </mesh>
          </geometry>
          <material>
            <script>
              <name>Gazebo/White</name>
              <uri>file://media/materials/scripts/gazebo.material</uri>
            </script>
          </material>
        </visual>
        <self_collide>0</self_collide>
        <enable_wind>0</enable_wind>
        <kinematic>0</kinematic>
      </link>
      <joint name='back_right_wheel_joint' type='revolute'>
        <pose relative_to='back_right_corner_link'>0 0 -0.132 0 -0 0</pose>
        <parent>back_right_corner_link</parent>
        <child>back_right_wheel_link</child>
        <axis>
          <xyz>0 1 0</xyz>
          <limit>
            <effort>1000</effort>
            <velocity>30</velocity>
            <lower>-1e+16</lower>
            <upper>1e+16</upper>
          </limit>
          <dynamics>
            <damping>0</damping>
            <friction>0</friction>
            <spring_reference>0</spring_reference>
            <spring_stiffness>0</spring_stiffness>
          </dynamics>
        </axis>
        <physics>
          <provide_feedback>1</provide_feedback>
          <ode>
            <limit>
              <cfm>0</cfm>
              <erp>0.2</erp>
            </limit>
            <provide_feedback>1</provide_feedback>
          </ode>
        </physics>
      </joint>
      <link name='back_right_wheel_link'>
        <pose relative_to='back_right_wheel_joint'>0 0 0 0 -0 0</pose>
        <inertial>
          <pose>0 0 0 0 -0 0</pose>
          <mass>0.25</mass>
          <inertia>
            <ixx>0.000433333</ixx>
            <ixy>0</ixy>
            <ixz>0</ixz>
            <iyy>0.000433333</iyy>
            <iyz>0</iyz>
            <izz>0.00045</izz>
          </inertia>
        </inertial>
        <collision name='back_right_wheel_link_collision'>
          <pose>0 0 0 -1.5708 0 0</pose>
          <geometry>
            <cylinder>
              <length>0.1</length>
              <radius>0.06</radius>
            </cylinder>
          </geometry>
          <surface>
            <contact>
              <ode>
                <kp>1e+07</kp>
                <kd>1</kd>
              </ode>
            </contact>
            <friction>
              <ode>
                <mu>100</mu>
                <mu2>100</mu2>
                <fdir1>1 0 0</fdir1>
              </ode>
              <torsional>
                <ode/>
              </torsional>
            </friction>
            <bounce/>
          </surface>
          <max_contacts>10</max_contacts>
        </collision>
        <visual name='back_right_wheel_link_visual'>
          <pose>0 0 0 -1.5708 0 0</pose>
          <geometry>
            <mesh>
              <scale>1 1 1</scale>
              <uri>model://rover_description/meshes/wheels/wheel_asm.stl</uri>
            </mesh>
          </geometry>
          <material>
            <script>
              <name>Gazebo/DarkGray</name>
              <uri>file://media/materials/scripts/gazebo.material</uri>
            </script>
          </material>
        </visual>
        <gravity>1</gravity>
        <self_collide>0</self_collide>
        <enable_wind>0</enable_wind>
        <kinematic>0</kinematic>
      </link>
      <joint name='mid_right_wheel_joint' type='revolute'>
        <pose relative_to='right_bogie_link'>0.1063 -0.0929 -0.0959 0 -0 0</pose>
        <parent>right_bogie_link</parent>
        <child>mid_right_wheel_link</child>
        <axis>
          <xyz>0 1 0</xyz>
          <limit>
            <effort>1000</effort>
            <velocity>30</velocity>
            <lower>-1e+16</lower>
            <upper>1e+16</upper>
          </limit>
          <dynamics>
            <damping>0</damping>
            <friction>0</friction>
            <spring_reference>0</spring_reference>
            <spring_stiffness>0</spring_stiffness>
          </dynamics>
        </axis>
        <physics>
          <provide_feedback>1</provide_feedback>
          <ode>
            <limit>
              <cfm>0</cfm>
              <erp>0.2</erp>
            </limit>
            <provide_feedback>1</provide_feedback>
          </ode>
        </physics>
      </joint>
      <link name='mid_right_wheel_link'>
        <pose relative_to='mid_right_wheel_joint'>0 0 0 0 -0 0</pose>
        <inertial>
          <pose>0 0 0 0 -0 0</pose>
          <mass>0.25</mass>
          <inertia>
            <ixx>0.000433333</ixx>
            <ixy>0</ixy>
            <ixz>0</ixz>
            <iyy>0.000433333</iyy>
            <iyz>0</iyz>
            <izz>0.00045</izz>
          </inertia>
        </inertial>
        <collision name='mid_right_wheel_link_collision'>
          <pose>0 0 0 -1.5708 0 0</pose>
          <geometry>
            <cylinder>
              <length>0.1</length>
              <radius>0.06</radius>
            </cylinder>
          </geometry>
          <surface>
            <contact>
              <ode>
                <kp>1e+07</kp>
                <kd>1</kd>
              </ode>
            </contact>
            <friction>
              <ode>
                <mu>100</mu>
                <mu2>100</mu2>
                <fdir1>1 0 0</fdir1>
              </ode>
              <torsional>
                <ode/>
              </torsional>
            </friction>
            <bounce/>
          </surface>
          <max_contacts>10</max_contacts>
        </collision>
        <visual name='mid_right_wheel_link_visual'>
          <pose>0 0 0 -1.5708 0 0</pose>
          <geometry>
            <mesh>
              <scale>1 1 1</scale>
              <uri>model://rover_description/meshes/wheels/wheel_asm.stl</uri>
            </mesh>
          </geometry>
          <material>
            <script>
              <name>Gazebo/DarkGray</name>
              <uri>file://media/materials/scripts/gazebo.material</uri>
            </script>
          </material>
        </visual>
        <gravity>1</gravity>
        <self_collide>0</self_collide>
        <enable_wind>0</enable_wind>
        <kinematic>0</kinematic>
      </link>
      <plugin name='gazebo_ros2_control' filename='libgazebo_ros2_control.so'>
        <parameters>/home/phoenix/dev_ws/install/rover_description/share/rover_description/config/control.yaml</parameters>
      </plugin>
      <plugin name='rover_joint_state' filename='libgazebo_ros_joint_state_publisher.so'>
        <update_rate>30</update_rate>
        <joint_name>left_rocker_joint</joint_name>
        <joint_name>right_rocker_joint</joint_name>
        <joint_name>left_bogie_joint</joint_name>
        <joint_name>right_bogie_joint</joint_name>
        <joint_name>diff_brace_joint</joint_name>
        <joint_name>back_left_turnbuckle_joint</joint_name>
        <joint_name>back_right_turnbuckle_joint</joint_name>
        <joint_name>front_left_turnbuckle_joint</joint_name>
        <joint_name>front_right_turnbuckle_joint</joint_name>
        <joint_name>front_left_corner_joint</joint_name>
        <joint_name>front_right_corner_joint</joint_name>
        <joint_name>back_left_corner_joint</joint_name>
        <joint_name>back_right_corner_joint</joint_name>
      </plugin>
      <link name='left_turnbuckle_link'>
        <pose>0.035 0.17 0.07 0 -0 0</pose>
        <visual name='left_turnbuckle_visual'>
          <pose>0 0 0 0 -0 0</pose>
          <geometry>
            <mesh>
              <uri>package://rover_description/meshes/bases/turnbuckle.stl</uri>
            </mesh>
          </geometry>
          <material>
            <script>
              <name>Gazebo/Blue</name>
              <uri>__default__</uri>
            </script>
          </material>
        </visual>
        <collision name='left_turnbuckle_collision'>
          <pose>0 0 0 3.14159 1.57079 3.14159</pose>
          <geometry>
            <cylinder>
              <length>0.07</length>
              <radius>0.0025</radius>
            </cylinder>
          </geometry>
          <max_contacts>10</max_contacts>
          <surface>
            <contact>
              <ode/>
            </contact>
            <bounce/>
            <friction>
              <torsional>
                <ode/>
              </torsional>
              <ode/>
            </friction>
          </surface>
        </collision>
        <inertial>
          <mass>0.01</mass>
          <inertia>
            <ixx>0.0001</ixx>
            <ixy>0</ixy>
            <ixz>0</ixz>
            <iyy>0.0001</iyy>
            <iyz>0</iyz>
            <izz>0.0001</izz>
          </inertia>
          <pose>0 0 0 0 -0 0</pose>
        </inertial>
        <self_collide>0</self_collide>
        <enable_wind>0</enable_wind>
        <kinematic>0</kinematic>
      </link>
      <joint name='back_left_turnbuckle_joint' type='ball'>
        <pose>-0.035 0 0 0 -0 0</pose>
        <parent>diff_brace_link</parent>
        <child>left_turnbuckle_link</child>
      </joint>
      <joint name='front_left_turnbuckle_joint' type='ball'>
        <pose>0.035 0 0 0 -0 0</pose>
        <parent>left_rocker_link</parent>
        <child>left_turnbuckle_link</child>
      </joint>
      <static>0</static>
      <link name='right_turnbuckle_link'>
        <pose>0.035 -0.17 0.07 0 -0 0</pose>
        <visual name='right_turnbuckle_visual'>
          <pose>0 0 0 0 -0 0</pose>
          <geometry>
            <mesh>
              <uri>package://rover_description/meshes/bases/turnbuckle.stl</uri>
            </mesh>
          </geometry>
          <material>
            <script>
              <name>Gazebo/Blue</name>
              <uri>__default__</uri>
            </script>
          </material>
        </visual>
        <collision name='right_turnbuckle_collision'>
          <pose>0 0 0 3.14159 1.57079 3.14159</pose>
          <geometry>
            <cylinder>
              <length>0.07</length>
              <radius>0.0025</radius>
            </cylinder>
          </geometry>
          <max_contacts>10</max_contacts>
          <surface>
            <contact>
              <ode/>
            </contact>
            <bounce/>
            <friction>
              <torsional>
                <ode/>
              </torsional>
              <ode/>
            </friction>
          </surface>
        </collision>
        <inertial>
          <mass>0.01</mass>
          <inertia>
            <ixx>0.0001</ixx>
            <ixy>0</ixy>
            <ixz>0</ixz>
            <iyy>0.0001</iyy>
            <iyz>0</iyz>
            <izz>0.0001</izz>
          </inertia>
          <pose>0 0 0 0 -0 0</pose>
        </inertial>
        <self_collide>0</self_collide>
        <enable_wind>0</enable_wind>
        <kinematic>0</kinematic>
      </link>
      <joint name='back_right_turnbuckle_joint' type='ball'>
        <pose>-0.035 0 0 0 -0 0</pose>
        <parent>diff_brace_link</parent>
        <child>right_turnbuckle_link</child>
      </joint>
      <joint name='front_right_turnbuckle_joint' type='ball'>
        <pose>0.035 0 0 0 -0 0</pose>
        <parent>right_rocker_link</parent>
        <child>right_turnbuckle_link</child>
      </joint>
      <pose>0 0 2.11 0 -0 0</pose>
    </model>
    <model name='rockformation'>
      <static>1</static>
      <link name='link'>
        <inertial>
          <mass>1</mass>
          <inertia>
            <ixx>0.166667</ixx>
            <ixy>0</ixy>
            <ixz>0</ixz>
            <iyy>0.166667</iyy>
            <iyz>0</iyz>
            <izz>0.166667</izz>
          </inertia>
          <pose>0 0 0 0 -0 0</pose>
        </inertial>
        <self_collide>1</self_collide>
        <kinematic>0</kinematic>
        <gravity>0</gravity>
        <collision name='collision'>
          <geometry>
            <mesh>
              <uri>model://rockformation/meshes/rockformation.dae</uri>
            </mesh>
          </geometry>
          <surface>
            <friction>
              <ode>
                <mu>1</mu>
                <mu2>1</mu2>
                <fdir1>0 0 0</fdir1>
                <slip1>0</slip1>
                <slip2>0</slip2>
              </ode>
              <torsional>
                <coefficient>1</coefficient>
                <patch_radius>0</patch_radius>
                <surface_radius>0</surface_radius>
                <use_patch_radius>1</use_patch_radius>
                <ode>
                  <slip>0</slip>
                </ode>
              </torsional>
            </friction>
            <bounce>
              <restitution_coefficient>0</restitution_coefficient>
              <threshold>1e+06</threshold>
            </bounce>
            <contact>
              <collide_without_contact>0</collide_without_contact>
              <collide_without_contact_bitmask>1</collide_without_contact_bitmask>
              <collide_bitmask>1</collide_bitmask>
              <ode>
                <soft_cfm>0</soft_cfm>
                <soft_erp>0.2</soft_erp>
                <kp>1e+13</kp>
                <kd>1</kd>
                <max_vel>0.01</max_vel>
                <min_depth>0</min_depth>
              </ode>
              <bullet>
                <split_impulse>1</split_impulse>
                <split_impulse_penetration_threshold>-0.01</split_impulse_penetration_threshold>
                <soft_cfm>0</soft_cfm>
                <soft_erp>0.2</soft_erp>
                <kp>1e+13</kp>
                <kd>1</kd>
              </bullet>
            </contact>
          </surface>
          <max_contacts>10</max_contacts>
        </collision>
        <visual name='visual'>
          <geometry>
            <mesh>
              <uri>model://rockformation/meshes/rockformation.dae</uri>
            </mesh>
          </geometry>
        </visual>
        <enable_wind>0</enable_wind>
      </link>
      <pose>0 0 0 0 -0 0</pose>
    </model>
    <model name='rockformation_0'>
      <static>1</static>
      <link name='link'>
        <inertial>
          <mass>1</mass>
          <inertia>
            <ixx>0.166667</ixx>
            <ixy>0</ixy>
            <ixz>0</ixz>
            <iyy>0.166667</iyy>
            <iyz>0</iyz>
            <izz>0.166667</izz>
          </inertia>
          <pose>0 0 0 0 -0 0</pose>
        </inertial>
        <self_collide>1</self_collide>
        <kinematic>0</kinematic>
        <gravity>0</gravity>
        <collision name='collision'>
          <geometry>
            <mesh>
              <uri>model://rockformation/meshes/rockformation.dae</uri>
            </mesh>
          </geometry>
          <surface>
            <friction>
              <ode>
                <mu>1</mu>
                <mu2>1</mu2>
                <fdir1>0 0 0</fdir1>
                <slip1>0</slip1>
                <slip2>0</slip2>
              </ode>
              <torsional>
                <coefficient>1</coefficient>
                <patch_radius>0</patch_radius>
                <surface_radius>0</surface_radius>
                <use_patch_radius>1</use_patch_radius>
                <ode>
                  <slip>0</slip>
                </ode>
              </torsional>
            </friction>
            <bounce>
              <restitution_coefficient>0</restitution_coefficient>
              <threshold>1e+06</threshold>
            </bounce>
            <contact>
              <collide_without_contact>0</collide_without_contact>
              <collide_without_contact_bitmask>1</collide_without_contact_bitmask>
              <collide_bitmask>1</collide_bitmask>
              <ode>
                <soft_cfm>0</soft_cfm>
                <soft_erp>0.2</soft_erp>
                <kp>1e+13</kp>
                <kd>1</kd>
                <max_vel>0.01</max_vel>
                <min_depth>0</min_depth>
              </ode>
              <bullet>
                <split_impulse>1</split_impulse>
                <split_impulse_penetration_threshold>-0.01</split_impulse_penetration_threshold>
                <soft_cfm>0</soft_cfm>
                <soft_erp>0.2</soft_erp>
                <kp>1e+13</kp>
                <kd>1</kd>
              </bullet>
            </contact>
          </surface>
          <max_contacts>10</max_contacts>
        </collision>
        <visual name='visual'>
          <geometry>
            <mesh>
              <uri>model://rockformation/meshes/rockformation.dae</uri>
            </mesh>
          </geometry>
        </visual>
        <enable_wind>0</enable_wind>
      </link>
      <pose>0 0 0 0 -0 0</pose>
    </model>
    <model name='rockformation_1'>
      <static>1</static>
      <link name='link'>
        <inertial>
          <mass>1</mass>
          <inertia>
            <ixx>0.166667</ixx>
            <ixy>0</ixy>
            <ixz>0</ixz>
            <iyy>0.166667</iyy>
            <iyz>0</iyz>
            <izz>0.166667</izz>
          </inertia>
          <pose>0 0 0 0 -0 0</pose>
        </inertial>
        <self_collide>1</self_collide>
        <kinematic>0</kinematic>
        <gravity>0</gravity>
        <collision name='collision'>
          <geometry>
            <mesh>
              <uri>model://rockformation/meshes/rockformation.dae</uri>
            </mesh>
          </geometry>
          <surface>
            <friction>
              <ode>
                <mu>1</mu>
                <mu2>1</mu2>
                <fdir1>0 0 0</fdir1>
                <slip1>0</slip1>
                <slip2>0</slip2>
              </ode>
              <torsional>
                <coefficient>1</coefficient>
                <patch_radius>0</patch_radius>
                <surface_radius>0</surface_radius>
                <use_patch_radius>1</use_patch_radius>
                <ode>
                  <slip>0</slip>
                </ode>
              </torsional>
            </friction>
            <bounce>
              <restitution_coefficient>0</restitution_coefficient>
              <threshold>1e+06</threshold>
            </bounce>
            <contact>
              <collide_without_contact>0</collide_without_contact>
              <collide_without_contact_bitmask>1</collide_without_contact_bitmask>
              <collide_bitmask>1</collide_bitmask>
              <ode>
                <soft_cfm>0</soft_cfm>
                <soft_erp>0.2</soft_erp>
                <kp>1e+13</kp>
                <kd>1</kd>
                <max_vel>0.01</max_vel>
                <min_depth>0</min_depth>
              </ode>
              <bullet>
                <split_impulse>1</split_impulse>
                <split_impulse_penetration_threshold>-0.01</split_impulse_penetration_threshold>
                <soft_cfm>0</soft_cfm>
                <soft_erp>0.2</soft_erp>
                <kp>1e+13</kp>
                <kd>1</kd>
              </bullet>
            </contact>
          </surface>
          <max_contacts>10</max_contacts>
        </collision>
        <visual name='visual'>
          <geometry>
            <mesh>
              <uri>model://rockformation/meshes/rockformation.dae</uri>
            </mesh>
          </geometry>
        </visual>
        <enable_wind>0</enable_wind>
      </link>
      <pose>0 0 0 0 -0 0</pose>
    </model>
    <model name='rockformation_2'>
      <static>1</static>
      <link name='link'>
        <inertial>
          <mass>1</mass>
          <inertia>
            <ixx>0.166667</ixx>
            <ixy>0</ixy>
            <ixz>0</ixz>
            <iyy>0.166667</iyy>
            <iyz>0</iyz>
            <izz>0.166667</izz>
          </inertia>
          <pose>0 0 0 0 -0 0</pose>
        </inertial>
        <self_collide>1</self_collide>
        <kinematic>0</kinematic>
        <gravity>0</gravity>
        <collision name='collision'>
          <geometry>
            <mesh>
              <uri>model://rockformation/meshes/rockformation.dae</uri>
            </mesh>
          </geometry>
          <surface>
            <friction>
              <ode>
                <mu>1</mu>
                <mu2>1</mu2>
                <fdir1>0 0 0</fdir1>
                <slip1>0</slip1>
                <slip2>0</slip2>
              </ode>
              <torsional>
                <coefficient>1</coefficient>
                <patch_radius>0</patch_radius>
                <surface_radius>0</surface_radius>
                <use_patch_radius>1</use_patch_radius>
                <ode>
                  <slip>0</slip>
                </ode>
              </torsional>
            </friction>
            <bounce>
              <restitution_coefficient>0</restitution_coefficient>
              <threshold>1e+06</threshold>
            </bounce>
            <contact>
              <collide_without_contact>0</collide_without_contact>
              <collide_without_contact_bitmask>1</collide_without_contact_bitmask>
              <collide_bitmask>1</collide_bitmask>
              <ode>
                <soft_cfm>0</soft_cfm>
                <soft_erp>0.2</soft_erp>
                <kp>1e+13</kp>
                <kd>1</kd>
                <max_vel>0.01</max_vel>
                <min_depth>0</min_depth>
              </ode>
              <bullet>
                <split_impulse>1</split_impulse>
                <split_impulse_penetration_threshold>-0.01</split_impulse_penetration_threshold>
                <soft_cfm>0</soft_cfm>
                <soft_erp>0.2</soft_erp>
                <kp>1e+13</kp>
                <kd>1</kd>
              </bullet>
            </contact>
          </surface>
          <max_contacts>10</max_contacts>
        </collision>
        <visual name='visual'>
          <geometry>
            <mesh>
              <uri>model://rockformation/meshes/rockformation.dae</uri>
            </mesh>
          </geometry>
        </visual>
        <enable_wind>0</enable_wind>
      </link>
      <pose>3.59543 2.44285 0 0 -0 0</pose>
    </model>
    <model name='rockformation_3'>
      <static>1</static>
      <link name='link'>
        <inertial>
          <mass>1</mass>
          <inertia>
            <ixx>0.166667</ixx>
            <ixy>0</ixy>
            <ixz>0</ixz>
            <iyy>0.166667</iyy>
            <iyz>0</iyz>
            <izz>0.166667</izz>
          </inertia>
          <pose>0 0 0 0 -0 0</pose>
        </inertial>
        <self_collide>1</self_collide>
        <kinematic>0</kinematic>
        <gravity>0</gravity>
        <collision name='collision'>
          <geometry>
            <mesh>
              <uri>model://rockformation/meshes/rockformation.dae</uri>
            </mesh>
          </geometry>
          <surface>
            <friction>
              <ode>
                <mu>1</mu>
                <mu2>1</mu2>
                <fdir1>0 0 0</fdir1>
                <slip1>0</slip1>
                <slip2>0</slip2>
              </ode>
              <torsional>
                <coefficient>1</coefficient>
                <patch_radius>0</patch_radius>
                <surface_radius>0</surface_radius>
                <use_patch_radius>1</use_patch_radius>
                <ode>
                  <slip>0</slip>
                </ode>
              </torsional>
            </friction>
            <bounce>
              <restitution_coefficient>0</restitution_coefficient>
              <threshold>1e+06</threshold>
            </bounce>
            <contact>
              <collide_without_contact>0</collide_without_contact>
              <collide_without_contact_bitmask>1</collide_without_contact_bitmask>
              <collide_bitmask>1</collide_bitmask>
              <ode>
                <soft_cfm>0</soft_cfm>
                <soft_erp>0.2</soft_erp>
                <kp>1e+13</kp>
                <kd>1</kd>
                <max_vel>0.01</max_vel>
                <min_depth>0</min_depth>
              </ode>
              <bullet>
                <split_impulse>1</split_impulse>
                <split_impulse_penetration_threshold>-0.01</split_impulse_penetration_threshold>
                <soft_cfm>0</soft_cfm>
                <soft_erp>0.2</soft_erp>
                <kp>1e+13</kp>
                <kd>1</kd>
              </bullet>
            </contact>
          </surface>
          <max_contacts>10</max_contacts>
        </collision>
        <visual name='visual'>
          <geometry>
            <mesh>
              <uri>model://rockformation/meshes/rockformation.dae</uri>
            </mesh>
          </geometry>
        </visual>
        <enable_wind>0</enable_wind>
      </link>
      <pose>-29.4127 -13.2758 0 0 -0 0</pose>
    </model>
    <model name='rockformation_4'>
      <static>1</static>
      <link name='link'>
        <inertial>
          <mass>1</mass>
          <inertia>
            <ixx>0.166667</ixx>
            <ixy>0</ixy>
            <ixz>0</ixz>
            <iyy>0.166667</iyy>
            <iyz>0</iyz>
            <izz>0.166667</izz>
          </inertia>
          <pose>0 0 0 0 -0 0</pose>
        </inertial>
        <self_collide>1</self_collide>
        <kinematic>0</kinematic>
        <gravity>0</gravity>
        <collision name='collision'>
          <geometry>
            <mesh>
              <uri>model://rockformation/meshes/rockformation.dae</uri>
            </mesh>
          </geometry>
          <surface>
            <friction>
              <ode>
                <mu>1</mu>
                <mu2>1</mu2>
                <fdir1>0 0 0</fdir1>
                <slip1>0</slip1>
                <slip2>0</slip2>
              </ode>
              <torsional>
                <coefficient>1</coefficient>
                <patch_radius>0</patch_radius>
                <surface_radius>0</surface_radius>
                <use_patch_radius>1</use_patch_radius>
                <ode>
                  <slip>0</slip>
                </ode>
              </torsional>
            </friction>
            <bounce>
              <restitution_coefficient>0</restitution_coefficient>
              <threshold>1e+06</threshold>
            </bounce>
            <contact>
              <collide_without_contact>0</collide_without_contact>
              <collide_without_contact_bitmask>1</collide_without_contact_bitmask>
              <collide_bitmask>1</collide_bitmask>
              <ode>
                <soft_cfm>0</soft_cfm>
                <soft_erp>0.2</soft_erp>
                <kp>1e+13</kp>
                <kd>1</kd>
                <max_vel>0.01</max_vel>
                <min_depth>0</min_depth>
              </ode>
              <bullet>
                <split_impulse>1</split_impulse>
                <split_impulse_penetration_threshold>-0.01</split_impulse_penetration_threshold>
                <soft_cfm>0</soft_cfm>
                <soft_erp>0.2</soft_erp>
                <kp>1e+13</kp>
                <kd>1</kd>
              </bullet>
            </contact>
          </surface>
          <max_contacts>10</max_contacts>
        </collision>
        <visual name='visual'>
          <geometry>
            <mesh>
              <uri>model://rockformation/meshes/rockformation.dae</uri>
            </mesh>
          </geometry>
        </visual>
        <enable_wind>0</enable_wind>
      </link>
      <pose>0 0 0 0 -0 0</pose>
    </model>
    <model name='rockformation_5'>
      <static>1</static>
      <link name='link'>
        <inertial>
          <mass>1</mass>
          <inertia>
            <ixx>0.166667</ixx>
            <ixy>0</ixy>
            <ixz>0</ixz>
            <iyy>0.166667</iyy>
            <iyz>0</iyz>
            <izz>0.166667</izz>
          </inertia>
          <pose>0 0 0 0 -0 0</pose>
        </inertial>
        <self_collide>1</self_collide>
        <kinematic>0</kinematic>
        <gravity>0</gravity>
        <collision name='collision'>
          <geometry>
            <mesh>
              <uri>model://rockformation/meshes/rockformation.dae</uri>
            </mesh>
          </geometry>
          <surface>
            <friction>
              <ode>
                <mu>1</mu>
                <mu2>1</mu2>
                <fdir1>0 0 0</fdir1>
                <slip1>0</slip1>
                <slip2>0</slip2>
              </ode>
              <torsional>
                <coefficient>1</coefficient>
                <patch_radius>0</patch_radius>
                <surface_radius>0</surface_radius>
                <use_patch_radius>1</use_patch_radius>
                <ode>
                  <slip>0</slip>
                </ode>
              </torsional>
            </friction>
            <bounce>
              <restitution_coefficient>0</restitution_coefficient>
              <threshold>1e+06</threshold>
            </bounce>
            <contact>
              <collide_without_contact>0</collide_without_contact>
              <collide_without_contact_bitmask>1</collide_without_contact_bitmask>
              <collide_bitmask>1</collide_bitmask>
              <ode>
                <soft_cfm>0</soft_cfm>
                <soft_erp>0.2</soft_erp>
                <kp>1e+13</kp>
                <kd>1</kd>
                <max_vel>0.01</max_vel>
                <min_depth>0</min_depth>
              </ode>
              <bullet>
                <split_impulse>1</split_impulse>
                <split_impulse_penetration_threshold>-0.01</split_impulse_penetration_threshold>
                <soft_cfm>0</soft_cfm>
                <soft_erp>0.2</soft_erp>
                <kp>1e+13</kp>
                <kd>1</kd>
              </bullet>
            </contact>
          </surface>
          <max_contacts>10</max_contacts>
        </collision>
        <visual name='visual'>
          <geometry>
            <mesh>
              <uri>model://rockformation/meshes/rockformation.dae</uri>
            </mesh>
          </geometry>
        </visual>
        <enable_wind>0</enable_wind>
      </link>
      <pose>85.781 -36.1934 0 0 -0 0</pose>
    </model>
    <model name='rockformation_6'>
      <static>1</static>
      <link name='link'>
        <inertial>
          <mass>1</mass>
          <inertia>
            <ixx>0.166667</ixx>
            <ixy>0</ixy>
            <ixz>0</ixz>
            <iyy>0.166667</iyy>
            <iyz>0</iyz>
            <izz>0.166667</izz>
          </inertia>
          <pose>0 0 0 0 -0 0</pose>
        </inertial>
        <self_collide>1</self_collide>
        <kinematic>0</kinematic>
        <gravity>0</gravity>
        <collision name='collision'>
          <geometry>
            <mesh>
              <uri>model://rockformation/meshes/rockformation.dae</uri>
            </mesh>
          </geometry>
          <surface>
            <friction>
              <ode>
                <mu>1</mu>
                <mu2>1</mu2>
                <fdir1>0 0 0</fdir1>
                <slip1>0</slip1>
                <slip2>0</slip2>
              </ode>
              <torsional>
                <coefficient>1</coefficient>
                <patch_radius>0</patch_radius>
                <surface_radius>0</surface_radius>
                <use_patch_radius>1</use_patch_radius>
                <ode>
                  <slip>0</slip>
                </ode>
              </torsional>
            </friction>
            <bounce>
              <restitution_coefficient>0</restitution_coefficient>
              <threshold>1e+06</threshold>
            </bounce>
            <contact>
              <collide_without_contact>0</collide_without_contact>
              <collide_without_contact_bitmask>1</collide_without_contact_bitmask>
              <collide_bitmask>1</collide_bitmask>
              <ode>
                <soft_cfm>0</soft_cfm>
                <soft_erp>0.2</soft_erp>
                <kp>1e+13</kp>
                <kd>1</kd>
                <max_vel>0.01</max_vel>
                <min_depth>0</min_depth>
              </ode>
              <bullet>
                <split_impulse>1</split_impulse>
                <split_impulse_penetration_threshold>-0.01</split_impulse_penetration_threshold>
                <soft_cfm>0</soft_cfm>
                <soft_erp>0.2</soft_erp>
                <kp>1e+13</kp>
                <kd>1</kd>
              </bullet>
            </contact>
          </surface>
          <max_contacts>10</max_contacts>
        </collision>
        <visual name='visual'>
          <geometry>
            <mesh>
              <uri>model://rockformation/meshes/rockformation.dae</uri>
            </mesh>
          </geometry>
        </visual>
        <enable_wind>0</enable_wind>
      </link>
      <pose>0 0 0 0 -0 0</pose>
    </model>
    <model name='rockformation_7'>
      <static>1</static>
      <link name='link'>
        <inertial>
          <mass>1</mass>
          <inertia>
            <ixx>0.166667</ixx>
            <ixy>0</ixy>
            <ixz>0</ixz>
            <iyy>0.166667</iyy>
            <iyz>0</iyz>
            <izz>0.166667</izz>
          </inertia>
          <pose>0 0 0 0 -0 0</pose>
        </inertial>
        <self_collide>1</self_collide>
        <kinematic>0</kinematic>
        <gravity>0</gravity>
        <collision name='collision'>
          <geometry>
            <mesh>
              <uri>model://rockformation/meshes/rockformation.dae</uri>
            </mesh>
          </geometry>
          <surface>
            <friction>
              <ode>
                <mu>1</mu>
                <mu2>1</mu2>
                <fdir1>0 0 0</fdir1>
                <slip1>0</slip1>
                <slip2>0</slip2>
              </ode>
              <torsional>
                <coefficient>1</coefficient>
                <patch_radius>0</patch_radius>
                <surface_radius>0</surface_radius>
                <use_patch_radius>1</use_patch_radius>
                <ode>
                  <slip>0</slip>
                </ode>
              </torsional>
            </friction>
            <bounce>
              <restitution_coefficient>0</restitution_coefficient>
              <threshold>1e+06</threshold>
            </bounce>
            <contact>
              <collide_without_contact>0</collide_without_contact>
              <collide_without_contact_bitmask>1</collide_without_contact_bitmask>
              <collide_bitmask>1</collide_bitmask>
              <ode>
                <soft_cfm>0</soft_cfm>
                <soft_erp>0.2</soft_erp>
                <kp>1e+13</kp>
                <kd>1</kd>
                <max_vel>0.01</max_vel>
                <min_depth>0</min_depth>
              </ode>
              <bullet>
                <split_impulse>1</split_impulse>
                <split_impulse_penetration_threshold>-0.01</split_impulse_penetration_threshold>
                <soft_cfm>0</soft_cfm>
                <soft_erp>0.2</soft_erp>
                <kp>1e+13</kp>
                <kd>1</kd>
              </bullet>
            </contact>
          </surface>
          <max_contacts>10</max_contacts>
        </collision>
        <visual name='visual'>
          <geometry>
            <mesh>
              <uri>model://rockformation/meshes/rockformation.dae</uri>
            </mesh>
          </geometry>
        </visual>
        <enable_wind>0</enable_wind>
      </link>
      <pose>7.18848 27.2976 0 0 -0 0</pose>
    </model>
    <state world_name='default'>
      <sim_time>822 849000000</sim_time>
      <real_time>871 311096271</real_time>
      <wall_time>1728439904 510775169</wall_time>
      <iterations>822849</iterations>
      <model name='moon'>
        <pose>0 0 0 0 -0 0</pose>
        <scale>1 1 1</scale>
        <link name='link'>
          <pose>0 0 0 0 -0 0</pose>
          <velocity>0 0 0 0 -0 0</velocity>
          <acceleration>0 0 0 0 -0 0</acceleration>
          <wrench>0 0 0 0 -0 0</wrench>
        </link>
      </model>
      <model name='rockformation'>
        <pose>-10.3035 -0.029108 1.64354 0 0 -0.087881</pose>
        <scale>1 1 1</scale>
        <link name='link'>
          <pose>-10.3035 -0.029108 1.64354 0 0 -0.087881</pose>
          <velocity>0 0 0 0 -0 0</velocity>
          <acceleration>0 0 0 0 -0 0</acceleration>
          <wrench>0 0 0 0 -0 0</wrench>
        </link>
      </model>
      <model name='rockformation_0'>
        <pose>8.22446 -15.4722 2.42125 0 -0 2.20682</pose>
        <scale>1 1 1</scale>
        <link name='link'>
          <pose>8.22446 -15.4722 2.42125 0 -0 2.20682</pose>
          <velocity>0 0 0 0 -0 0</velocity>
          <acceleration>0 0 0 0 -0 0</acceleration>
          <wrench>0 0 0 0 -0 0</wrench>
        </link>
      </model>
      <model name='rockformation_1'>
        <pose>-5.79741 20.4482 1.23943 0.03116 0.067625 0.413094</pose>
        <scale>1 1 1</scale>
        <link name='link'>
          <pose>-5.79741 20.4482 1.23943 0.03116 0.067625 0.413094</pose>
          <velocity>0 0 0 0 -0 0</velocity>
          <acceleration>0 0 0 0 -0 0</acceleration>
          <wrench>0 0 0 0 -0 0</wrench>
        </link>
      </model>
      <model name='rockformation_2'>
        <pose>-22.8944 -23.1242 2.38845 0 -0 0.629384</pose>
        <scale>1 1 1</scale>
        <link name='link'>
          <pose>-22.8944 -23.1242 2.38845 0 -0 0.629384</pose>
          <velocity>0 0 0 0 -0 0</velocity>
          <acceleration>0 0 0 0 -0 0</acceleration>
          <wrench>0 0 0 0 -0 0</wrench>
        </link>
      </model>
      <model name='rockformation_3'>
        <pose>-32.0276 -1.48277 0.041348 -0.026298 -0.036953 0.401238</pose>
        <scale>1 1 1</scale>
        <link name='link'>
          <pose>-32.0276 -1.48277 0.041348 -0.026298 -0.036953 0.401238</pose>
          <velocity>0 0 0 0 -0 0</velocity>
          <acceleration>0 0 0 0 -0 0</acceleration>
          <wrench>0 0 0 0 -0 0</wrench>
        </link>
      </model>
      <model name='rockformation_4'>
        <pose>22.4961 17.7909 2.37771 -0.003867 0.037725 -0.746237</pose>
        <scale>1 1 1</scale>
        <link name='link'>
          <pose>22.4961 17.7909 2.37771 -0.003867 0.037725 -0.746237</pose>
          <velocity>0 0 0 0 -0 0</velocity>
          <acceleration>0 0 0 0 -0 0</acceleration>
          <wrench>0 0 0 0 -0 0</wrench>
        </link>
      </model>
      <model name='rockformation_5'>
        <pose>29.8489 -27.8736 4.47334 0.041224 0 -2.30906</pose>
        <scale>1 1 1</scale>
        <link name='link'>
          <pose>29.8489 -27.8736 4.47334 0.041224 0 -2.30906</pose>
          <velocity>0 0 0 0 -0 0</velocity>
          <acceleration>0 0 0 0 -0 0</acceleration>
          <wrench>0 0 0 0 -0 0</wrench>
        </link>
      </model>
      <model name='rockformation_6'>
        <pose>-30.8713 29.6986 1.08764 -0.085029 -0 1.45398</pose>
        <scale>1 1 1</scale>
        <link name='link'>
          <pose>-30.8713 29.6986 1.08764 -0.085029 -0 1.45398</pose>
          <velocity>0 0 0 0 -0 0</velocity>
          <acceleration>0 0 0 0 -0 0</acceleration>
          <wrench>0 0 0 0 -0 0</wrench>
        </link>
      </model>
      <model name='rockformation_7'>
        <pose>6.91469 27.5943 1.24813 0.144354 -0 0.510965</pose>
        <scale>1 1 1</scale>
        <link name='link'>
          <pose>6.91469 27.5943 1.24813 0.144354 -0 0.510965</pose>
          <velocity>0 0 0 0 -0 0</velocity>
          <acceleration>0 0 0 0 -0 0</acceleration>
          <wrench>0 0 0 0 -0 0</wrench>
        </link>
      </model>
      <model name='rover'>
        <pose>1.55113 -2.82849 1.91585 0.085882 0.0002 0.532011</pose>
        <scale>1 1 1</scale>
        <link name='back_left_corner_link'>
          <pose>1.21221 -2.76134 1.92823 0.085976 0.045902 0.535949</pose>
          <velocity>4.5e-05 2.4e-05 -1e-06 1.9e-05 -1e-05 0.000202</velocity>
          <acceleration>-0.000224 0.000113 -0.000785 -0.00752 -0.014849 0.198988</acceleration>
          <wrench>-5.6e-05 2.8e-05 -0.000196 0 -0 0</wrench>
        </link>
        <link name='back_left_wheel_link'>
          <pose>1.20123 -2.75468 1.79686 0.09498 -0.440528 0.491393</pose>
          <velocity>4.5e-05 2.4e-05 -1e-06 -0.000307 0.000556 0.00026</velocity>
          <acceleration>5.8e-05 0.000451 -0.000798 -0.305068 0.555818 0.258958</acceleration>
          <wrench>1.5e-05 0.000113 -0.0002 0 -0 0</wrench>
        </link>
        <link name='back_right_corner_link'>
          <pose>1.44454 -3.1555 1.87988 0.085892 0.014862 0.533272</pose>
          <velocity>4.7e-05 2.4e-05 -0 -3e-06 -4e-06 -4.9e-05</velocity>
          <acceleration>-0.000227 -2.3e-05 -0.000762 0.000693 0.00017 -0.055113</acceleration>
          <wrench>-5.7e-05 -6e-06 -0.000191 0 -0 0</wrench>
        </link>
        <link name='back_right_wheel_link'>
          <pose>1.4371 -3.14675 1.74839 0.118827 0.761751 0.614205</pose>
          <velocity>4.7e-05 2.4e-05 -0 -0.000526 0.000877 4e-05</velocity>
          <acceleration>9.8e-05 -1.7e-05 -0.000743 -0.524151 0.882004 0.036762</acceleration>
          <wrench>2.5e-05 -4e-06 -0.000186 0 -0 0</wrench>
        </link>
        <link name='base_link'>
          <pose>1.55113 -2.82849 1.91585 0.085882 0.0002 0.532011</pose>
          <velocity>4.5e-05 2.5e-05 0 3e-06 -8e-06 4e-06</velocity>
          <acceleration>-0.000114 5e-06 -0.000135 -5.6e-05 0.000437 -4e-05</acceleration>
          <wrench>-0.000116 5e-06 -0.000137 0 -0 0</wrench>
        </link>
        <link name='diff_brace_link'>
          <pose>1.55411 -2.83351 1.9837 0.08588 0.000549 0.527941</pose>
          <velocity>4.4e-05 2.5e-05 0 3e-06 -8e-06 6e-06</velocity>
          <acceleration>-8.6e-05 2.3e-05 -0.000134 -0.001271 0.001801 0.00021</acceleration>
          <wrench>-9e-06 2e-06 -1.3e-05 0 -0 0</wrench>
        </link>
        <link name='front_left_corner_link'>
          <pose>1.67732 -2.48645 1.91696 0.08589 0.012141 0.533039</pose>
          <velocity>4.3e-05 2.5e-05 3e-06 -1.4e-05 1.6e-05 -0.00035</velocity>
          <acceleration>-4e-05 -2e-06 -3.5e-05 0.007458 0.019657 -0.35423</acceleration>
          <wrench>-1e-05 -0 -9e-06 0 -0 0</wrench>
        </link>
        <link name='front_left_wheel_link'>
          <pose>1.67019 -2.47751 1.78546 3.02535 0.738339 -2.68803</pose>
          <velocity>4.4e-05 2.6e-05 3e-06 -0.000328 0.000552 -0.000296</velocity>
          <acceleration>6.2e-05 6.9e-05 -3.5e-05 -0.338947 0.556153 -0.304049</acceleration>
          <wrench>1.6e-05 1.7e-05 -9e-06 0 -0 0</wrench>
        </link>
        <link name='front_right_corner_link'>
          <pose>1.91059 -2.88145 1.88253 0.085888 -0.011611 0.530994</pose>
          <velocity>4.5e-05 2.7e-05 2e-06 1e-06 -1e-05 7.6e-05</velocity>
          <acceleration>-0.000102 -1.2e-05 -9.8e-05 -0.000786 -0.004786 0.070254</acceleration>
          <wrench>-2.5e-05 -3e-06 -2.4e-05 0 -0 0</wrench>
        </link>
        <link name='front_right_wheel_link'>
          <pose>1.90617 -2.87091 1.75102 0.305171 1.28127 0.825193</pose>
          <velocity>4.6e-05 2.6e-05 2e-06 -0.000413 0.000687 0.000145</velocity>
          <acceleration>-6e-06 3.5e-05 -0.000202 -0.412291 0.69097 0.144098</acceleration>
          <wrench>-2e-06 9e-06 -5e-05 0 -0 0</wrench>
        </link>
        <link name='left_bogie_link'>
          <pose>1.36264 -2.72656 1.88346 0.085975 0.045903 0.535948</pose>
          <velocity>4.5e-05 2.4e-05 -1e-06 1e-06 -0 4e-06</velocity>
          <acceleration>-6.3e-05 5.3e-05 -0.000296 -1.3e-05 -0.002822 -0.000329</acceleration>
          <wrench>-1.6e-05 1.3e-05 -7.4e-05 0 -0 0</wrench>
        </link>
        <link name='left_rocker_link'>
          <pose>1.5345 -2.66025 1.94089 0.08589 0.012141 0.533039</pose>
          <velocity>4.4e-05 2.5e-05 1e-06 5e-06 -8e-06 4e-06</velocity>
          <acceleration>-9.1e-05 1.1e-05 -0.000161 -5.2e-05 -0.000821 -0.000147</acceleration>
          <wrench>-2.3e-05 3e-06 -4e-05 0 -0 0</wrench>
        </link>
        <link name='left_turnbuckle_link'>
          <pose>1.49904 -2.66958 2.00017 0.37348 8.6e-05 0.532021</pose>
          <velocity>4.3e-05 2.4e-05 0 0.000133 7e-05 5e-06</velocity>
          <acceleration>-0.000148 -2e-05 -0.00015 -0.000238 0.000404 -6.6e-05</acceleration>
          <wrench>-1e-06 -0 -1e-06 0 -0 0</wrench>
        </link>
        <link name='mid_left_wheel_link'>
          <pose>1.39901 -2.58772 1.79111 0.088874 0.259608 0.554864</pose>
          <velocity>4.4e-05 2.4e-05 -1e-06 -0.000426 0.000726 7.7e-05</velocity>
          <acceleration>0.000237 3.5e-05 -0.000176 -0.426576 0.72419 0.075363</acceleration>
          <wrench>5.9e-05 9e-06 -4.4e-05 0 -0 0</wrench>
        </link>
        <link name='mid_right_wheel_link'>
          <pose>1.67874 -3.05396 1.7432 0.237243 1.19721 0.753419</pose>
          <velocity>4.7e-05 2.5e-05 1e-06 -0.000375 0.000632 7e-05</velocity>
          <acceleration>0.000113 0.000199 -0.000149 -0.373634 0.636723 0.066571</acceleration>
          <wrench>2.8e-05 5e-05 -3.7e-05 0 -0 0</wrench>
        </link>
        <link name='right_bogie_link'>
          <pose>1.54566 -3.03459 1.84829 0.085891 0.014863 0.533272</pose>
          <velocity>4.6e-05 2.5e-05 1e-06 0 -7e-06 6e-06</velocity>
          <acceleration>-0.000105 3.1e-05 -0.000295 -5.7e-05 -0.002923 -0.000388</acceleration>
          <wrench>-2.6e-05 8e-06 -7.4e-05 0 -0 0</wrench>
        </link>
        <link name='right_rocker_link'>
          <pose>1.69117 -2.92643 1.9143 0.085888 -0.011611 0.530993</pose>
          <velocity>4.5e-05 2.5e-05 1e-06 -1e-06 -5e-06 5e-06</velocity>
          <acceleration>-0.000123 -5e-06 -0.000176 -7.2e-05 -0.00071 -0.000156</acceleration>
          <wrench>-3.1e-05 -1e-06 -4.4e-05 0 -0 0</wrench>
        </link>
        <link name='right_turnbuckle_link'>
          <pose>1.66967 -2.96221 1.971 0.482445 0.000426 0.532009</pose>
          <velocity>4.5e-05 2.5e-05 1e-06 0.001098 0.000635 4e-06</velocity>
          <acceleration>-9.3e-05 1.7e-05 -0.000154 -0.000314 0.000533 2.6e-05</acceleration>
          <wrench>-1e-06 0 -2e-06 0 -0 0</wrench>
        </link>
      </model>
      <light name='sun_directional'>
        <pose>200 0 14 0 -0 0</pose>
      </light>
    </state>
    <gui fullscreen='0'>
      <camera name='user_camera'>
        <pose>-30.987 32.8004 61.7447 0 0.935458 -1.02143</pose>
        <view_controller>orbit</view_controller>
        <projection_type>perspective</projection_type>
      </camera>
    </gui>
  </world>
</sdf>
